<sdf version='1.7'>
  <world name='default'>
    <light name='sun' type='directional'>
      <cast_shadows>1</cast_shadows>
      <pose>0 0 10 0 -0 0</pose>
      <diffuse>0.8 0.8 0.8 1</diffuse>
      <specular>0.2 0.2 0.2 1</specular>
      <attenuation>
        <range>1000</range>
        <constant>0.9</constant>
        <linear>0.01</linear>
        <quadratic>0.001</quadratic>
      </attenuation>
      <direction>-0.5 0.1 -0.9</direction>
      <spot>
        <inner_angle>0</inner_angle>
        <outer_angle>0</outer_angle>
        <falloff>0</falloff>
      </spot>
    </light>
    <model name='ground_plane'>
      <static>1</static>
      <link name='link'>
        <collision name='collision'>
          <geometry>
            <plane>
              <normal>0 0 1</normal>
              <size>100 100</size>
            </plane>
          </geometry>
          <surface>
            <contact>
              <collide_bitmask>65535</collide_bitmask>
              <ode/>
            </contact>
            <friction>
              <ode>
                <mu>100</mu>
                <mu2>50</mu2>
              </ode>
              <torsional>
                <ode/>
              </torsional>
            </friction>
            <bounce/>
          </surface>
          <max_contacts>10</max_contacts>
        </collision>
        <visual name='visual'>
          <cast_shadows>0</cast_shadows>
          <geometry>
            <plane>
              <normal>0 0 1</normal>
              <size>100 100</size>
            </plane>
          </geometry>
          <material>
            <script>
              <uri>file://media/materials/scripts/gazebo.material</uri>
              <name>Gazebo/Grey</name>
            </script>
          </material>
        </visual>
        <self_collide>0</self_collide>
        <enable_wind>0</enable_wind>
        <kinematic>0</kinematic>
      </link>
    </model>
    <gravity>0 0 -9.8</gravity>
    <magnetic_field>6e-06 2.3e-05 -4.2e-05</magnetic_field>
    <atmosphere type='adiabatic'/>
    <physics type='ode'>
      <max_step_size>0.001</max_step_size>
      <real_time_factor>1</real_time_factor>
      <real_time_update_rate>1000</real_time_update_rate>
    </physics>
    <scene>
      <ambient>0.4 0.4 0.4 1</ambient>
      <background>0.7 0.7 0.7 1</background>
      <shadows>1</shadows>
    </scene>
    <audio>
      <device>default</device>
    </audio>
    <wind/>
    <spherical_coordinates>
      <surface_model>EARTH_WGS84</surface_model>
      <latitude_deg>0</latitude_deg>
      <longitude_deg>0</longitude_deg>
      <elevation>0</elevation>
      <heading_deg>0</heading_deg>
    </spherical_coordinates>
    <model name='cabinet'>
      <static>1</static>
      <link name='cabinet_bottom_plate'>
        <inertial>
          <pose>0 0 -1 0 -0 0</pose>
          <inertia>
            <ixx>2.05</ixx>
            <ixy>0</ixy>
            <ixz>0</ixz>
            <iyy>2.05</iyy>
            <iyz>0</iyz>
            <izz>2.05</izz>
          </inertia>
          <mass>25</mass>
        </inertial>
        <collision name='cabinet_bottom_plate_geom'>
          <pose>0 0 0.01 0 -0 0</pose>
          <geometry>
            <box>
              <size>0.45 0.45 0.02</size>
            </box>
          </geometry>
          <max_contacts>10</max_contacts>
          <surface>
            <contact>
              <ode/>
            </contact>
            <bounce/>
            <friction>
              <torsional>
                <ode/>
              </torsional>
              <ode/>
            </friction>
          </surface>
        </collision>
        <visual name='cabinet_bottom_plate_geom_visual'>
          <pose>0 0 0.01 0 -0 0</pose>
          <geometry>
            <box>
              <size>0.45 0.45 0.02</size>
            </box>
          </geometry>
          <material>
            <script>
              <uri>file://media/materials/scripts/gazebo.material</uri>
              <name>Gazebo/Wood</name>
            </script>
          </material>
        </visual>
        <collision name='cabinet_bottom_plate_geom_cabinet_back_plate'>
          <pose>0.235 0 0.51 0 -0 0</pose>
          <geometry>
            <box>
              <size>0.02 0.45 1.02</size>
            </box>
          </geometry>
          <max_contacts>10</max_contacts>
          <surface>
            <contact>
              <ode/>
            </contact>
            <bounce/>
            <friction>
              <torsional>
                <ode/>
              </torsional>
              <ode/>
            </friction>
          </surface>
        </collision>
        <visual name='cabinet_bottom_plate_geom_cabinet_back_plate_visual'>
          <pose>0.235 0 0.51 0 -0 0</pose>
          <geometry>
            <box>
              <size>0.02 0.45 1.02</size>
            </box>
          </geometry>
          <material>
            <script>
              <uri>file://media/materials/scripts/gazebo.material</uri>
              <name>Gazebo/Wood</name>
            </script>
          </material>
        </visual>
        <collision name='cabinet_bottom_plate_geom_cabinet_left_plate'>
          <pose>0 0.235 0.51 0 -0 0</pose>
          <geometry>
            <box>
              <size>0.45 0.02 1.02</size>
            </box>
          </geometry>
          <max_contacts>10</max_contacts>
          <surface>
            <contact>
              <ode/>
            </contact>
            <bounce/>
            <friction>
              <torsional>
                <ode/>
              </torsional>
              <ode/>
            </friction>
          </surface>
        </collision>
        <visual name='cabinet_bottom_plate_geom_cabinet_left_plate_visual'>
          <pose>0 0.235 0.51 0 -0 0</pose>
          <geometry>
            <box>
              <size>0.45 0.02 1.02</size>
            </box>
          </geometry>
          <material>
            <script>
              <uri>file://media/materials/scripts/gazebo.material</uri>
              <name>Gazebo/Wood</name>
            </script>
          </material>
        </visual>
        <collision name='cabinet_bottom_plate_geom_cabinet_middle_plate'>
          <pose>0 0 0.51 0 -0 0</pose>
          <geometry>
            <box>
              <size>0.45 0.45 0.02</size>
            </box>
          </geometry>
          <max_contacts>10</max_contacts>
          <surface>
            <contact>
              <ode/>
            </contact>
            <bounce/>
            <friction>
              <torsional>
                <ode/>
              </torsional>
              <ode/>
            </friction>
          </surface>
        </collision>
        <visual name='cabinet_bottom_plate_geom_cabinet_middle_plate_visual'>
          <pose>0 0 0.51 0 -0 0</pose>
          <geometry>
            <box>
              <size>0.45 0.45 0.02</size>
            </box>
          </geometry>
          <material>
            <script>
              <uri>file://media/materials/scripts/gazebo.material</uri>
              <name>Gazebo/Wood</name>
            </script>
          </material>
        </visual>
        <collision name='cabinet_bottom_plate_geom_cabinet_right_plate'>
          <pose>0 -0.235 0.51 0 -0 0</pose>
          <geometry>
            <box>
              <size>0.45 0.02 1.02</size>
            </box>
          </geometry>
          <max_contacts>10</max_contacts>
          <surface>
            <contact>
              <ode/>
            </contact>
            <bounce/>
            <friction>
              <torsional>
                <ode/>
              </torsional>
              <ode/>
            </friction>
          </surface>
        </collision>
        <visual name='cabinet_bottom_plate_geom_cabinet_right_plate_visual'>
          <pose>0 -0.235 0.51 0 -0 0</pose>
          <geometry>
            <box>
              <size>0.45 0.02 1.02</size>
            </box>
          </geometry>
          <material>
            <script>
              <uri>file://media/materials/scripts/gazebo.material</uri>
              <name>Gazebo/Wood</name>
            </script>
          </material>
        </visual>
        <collision name='cabinet_bottom_plate_geom_cabinet_top_plate'>
          <pose>0 0 1.01 0 -0 0</pose>
          <geometry>
            <box>
              <size>0.45 0.45 0.02</size>
            </box>
          </geometry>
          <max_contacts>10</max_contacts>
          <surface>
            <contact>
              <ode/>
            </contact>
            <bounce/>
            <friction>
              <torsional>
                <ode/>
              </torsional>
              <ode/>
            </friction>
          </surface>
        </collision>
        <visual name='cabinet_bottom_plate_geom_cabinet_top_plate_visual'>
          <pose>0 0 1.01 0 -0 0</pose>
          <geometry>
            <box>
              <size>0.45 0.45 0.02</size>
            </box>
          </geometry>
          <material>
            <script>
              <uri>file://media/materials/scripts/gazebo.material</uri>
              <name>Gazebo/Wood</name>
            </script>
          </material>
        </visual>
        <self_collide>0</self_collide>
        <enable_wind>0</enable_wind>
        <kinematic>0</kinematic>
      </link>
      <pose>-0.185929 -0.852549 0 0 -0 0</pose>
    </model>
    <model name='cessna_c172'>
      <pose>-2.29166 4.74233 0.495 0 -0 0</pose>
      <link name='body'>
        <inertial>
          <mass>680.389</mass>
          <inertia>
            <ixx>1285.32</ixx>
            <ixy>0</ixy>
            <iyy>1824.93</iyy>
            <ixz>0</ixz>
            <iyz>0</iyz>
            <izz>2666.89</izz>
          </inertia>
          <pose>-0.0414 0 0.9271 0 -0 0</pose>
        </inertial>
        <collision name='collision'>
          <geometry>
            <mesh>
              <uri>model://cessna/meshes/body.dae</uri>
            </mesh>
          </geometry>
          <max_contacts>10</max_contacts>
          <surface>
            <contact>
              <ode/>
            </contact>
            <bounce/>
            <friction>
              <torsional>
                <ode/>
              </torsional>
              <ode/>
            </friction>
          </surface>
        </collision>
        <visual name='visual'>
          <geometry>
            <mesh>
              <uri>model://cessna/meshes/body.dae</uri>
            </mesh>
          </geometry>
        </visual>
        <self_collide>0</self_collide>
        <enable_wind>0</enable_wind>
        <kinematic>0</kinematic>
      </link>
      <link name='left_aileron'>
        <inertial>
          <mass>2</mass>
          <inertia>
            <ixx>0.8434</ixx>
            <ixy>0</ixy>
            <iyy>0.0119</iyy>
            <ixz>0</ixz>
            <iyz>0</iyz>
            <izz>0.855</izz>
          </inertia>
          <pose>-1.65 3.7 1.5 0.05 -0 -0.12</pose>
        </inertial>
        <collision name='collision'>
          <geometry>
            <mesh>
              <uri>model://cessna/meshes/left_aileron.dae</uri>
            </mesh>
          </geometry>
          <max_contacts>10</max_contacts>
          <surface>
            <contact>
              <ode/>
            </contact>
            <bounce/>
            <friction>
              <torsional>
                <ode/>
              </torsional>
              <ode/>
            </friction>
          </surface>
        </collision>
        <visual name='visual'>
          <geometry>
            <mesh>
              <uri>model://cessna/meshes/left_aileron.dae</uri>
            </mesh>
          </geometry>
        </visual>
        <self_collide>0</self_collide>
        <enable_wind>0</enable_wind>
        <kinematic>0</kinematic>
      </link>
      <link name='left_flap'>
        <inertial>
          <mass>2</mass>
          <inertia>
            <ixx>0.6747</ixx>
            <ixy>0</ixy>
            <iyy>0.0242</iyy>
            <ixz>0</ixz>
            <iyz>0</iyz>
            <izz>0.6962</izz>
          </inertia>
          <pose>-1.8 1.55 1.43 0.02 -0 0</pose>
        </inertial>
        <collision name='collision'>
          <geometry>
            <mesh>
              <uri>model://cessna/meshes/left_flap.dae</uri>
            </mesh>
          </geometry>
          <max_contacts>10</max_contacts>
          <surface>
            <contact>
              <ode/>
            </contact>
            <bounce/>
            <friction>
              <torsional>
                <ode/>
              </torsional>
              <ode/>
            </friction>
          </surface>
        </collision>
        <visual name='visual'>
          <geometry>
            <mesh>
              <uri>model://cessna/meshes/left_flap.dae</uri>
            </mesh>
          </geometry>
        </visual>
        <self_collide>0</self_collide>
        <enable_wind>0</enable_wind>
        <kinematic>0</kinematic>
      </link>
      <link name='right_aileron'>
        <inertial>
          <mass>2</mass>
          <inertia>
            <ixx>0.8434</ixx>
            <ixy>0</ixy>
            <iyy>0.0119</iyy>
            <ixz>0</ixz>
            <iyz>0</iyz>
            <izz>0.855</izz>
          </inertia>
          <pose>-1.65 -3.7 1.5 -0.05 -0 0.12</pose>
        </inertial>
        <collision name='collision'>
          <geometry>
            <mesh>
              <uri>model://cessna/meshes/right_aileron.dae</uri>
            </mesh>
          </geometry>
          <max_contacts>10</max_contacts>
          <surface>
            <contact>
              <ode/>
            </contact>
            <bounce/>
            <friction>
              <torsional>
                <ode/>
              </torsional>
              <ode/>
            </friction>
          </surface>
        </collision>
        <visual name='visual'>
          <geometry>
            <mesh>
              <uri>model://cessna/meshes/right_aileron.dae</uri>
            </mesh>
          </geometry>
        </visual>
        <self_collide>0</self_collide>
        <enable_wind>0</enable_wind>
        <kinematic>0</kinematic>
      </link>
      <link name='right_flap'>
        <inertial>
          <mass>2</mass>
          <inertia>
            <ixx>0.6747</ixx>
            <ixy>0</ixy>
            <iyy>0.0242</iyy>
            <ixz>0</ixz>
            <iyz>0</iyz>
            <izz>0.6962</izz>
          </inertia>
          <pose>-1.8 -1.55 1.43 -0.02 0 0</pose>
        </inertial>
        <collision name='collision'>
          <geometry>
            <mesh>
              <uri>model://cessna/meshes/right_flap.dae</uri>
            </mesh>
          </geometry>
          <max_contacts>10</max_contacts>
          <surface>
            <contact>
              <ode/>
            </contact>
            <bounce/>
            <friction>
              <torsional>
                <ode/>
              </torsional>
              <ode/>
            </friction>
          </surface>
        </collision>
        <visual name='visual'>
          <geometry>
            <mesh>
              <uri>model://cessna/meshes/right_flap.dae</uri>
            </mesh>
          </geometry>
        </visual>
        <self_collide>0</self_collide>
        <enable_wind>0</enable_wind>
        <kinematic>0</kinematic>
      </link>
      <link name='elevators'>
        <inertial>
          <mass>2</mass>
          <inertia>
            <ixx>1.5008</ixx>
            <ixy>0</ixy>
            <iyy>0.0274</iyy>
            <ixz>0</ixz>
            <iyz>0</iyz>
            <izz>1.5266</izz>
          </inertia>
          <pose>-5.75 0 0.57 0 -0 0</pose>
        </inertial>
        <collision name='collision'>
          <geometry>
            <mesh>
              <uri>model://cessna/meshes/elevators.dae</uri>
            </mesh>
          </geometry>
          <max_contacts>10</max_contacts>
          <surface>
            <contact>
              <ode/>
            </contact>
            <bounce/>
            <friction>
              <torsional>
                <ode/>
              </torsional>
              <ode/>
            </friction>
          </surface>
        </collision>
        <visual name='visual'>
          <geometry>
            <mesh>
              <uri>model://cessna/meshes/elevators.dae</uri>
            </mesh>
          </geometry>
        </visual>
        <self_collide>0</self_collide>
        <enable_wind>0</enable_wind>
        <kinematic>0</kinematic>
      </link>
      <link name='rudder'>
        <inertial>
          <mass>2</mass>
          <inertia>
            <ixx>0.4708</ixx>
            <ixy>0</ixy>
            <iyy>0.5208</iyy>
            <ixz>0</ixz>
            <iyz>0</iyz>
            <izz>0.0508</izz>
          </inertia>
          <pose>-6.1 0 1.3 0 -0.35 0</pose>
        </inertial>
        <collision name='collision'>
          <geometry>
            <mesh>
              <uri>model://cessna/meshes/rudder.dae</uri>
            </mesh>
          </geometry>
          <max_contacts>10</max_contacts>
          <surface>
            <contact>
              <ode/>
            </contact>
            <bounce/>
            <friction>
              <torsional>
                <ode/>
              </torsional>
              <ode/>
            </friction>
          </surface>
        </collision>
        <visual name='visual'>
          <geometry>
            <mesh>
              <uri>model://cessna/meshes/rudder.dae</uri>
            </mesh>
          </geometry>
        </visual>
        <self_collide>0</self_collide>
        <enable_wind>0</enable_wind>
        <kinematic>0</kinematic>
      </link>
      <link name='propeller'>
        <pose>1.79 0 0.855 0 -0 0</pose>
        <inertial>
          <mass>18.37</mass>
          <inertia>
            <ixx>7.5067</ixx>
            <ixy>0</ixy>
            <iyy>7.515</iyy>
            <ixz>0</ixz>
            <iyz>0</iyz>
            <izz>0.068275</izz>
          </inertia>
          <pose>-0.35 0 0 0 -0 0</pose>
        </inertial>
        <collision name='collision'>
          <geometry>
            <mesh>
              <uri>model://cessna/meshes/cessna_prop.dae</uri>
            </mesh>
          </geometry>
          <max_contacts>10</max_contacts>
          <surface>
            <contact>
              <ode/>
            </contact>
            <bounce/>
            <friction>
              <torsional>
                <ode/>
              </torsional>
              <ode/>
            </friction>
          </surface>
        </collision>
        <visual name='visual'>
          <geometry>
            <mesh>
              <uri>model://cessna/meshes/cessna_prop.dae</uri>
            </mesh>
          </geometry>
        </visual>
        <self_collide>0</self_collide>
        <enable_wind>0</enable_wind>
        <kinematic>0</kinematic>
      </link>
      <link name='front_wheel'>
        <inertial>
          <mass>2</mass>
          <inertia>
            <ixx>0.01786</ixx>
            <ixy>0</ixy>
            <iyy>0.01786</iyy>
            <ixz>0</ixz>
            <iyz>0</iyz>
            <izz>0.0324</izz>
          </inertia>
          <pose>0.712 0 -0.313 1.57079 -0 0</pose>
        </inertial>
        <collision name='collision'>
          <pose>0.712 0 -0.313 1.57079 -0 0</pose>
          <geometry>
            <cylinder>
              <radius>0.18</radius>
              <length>0.1</length>
            </cylinder>
          </geometry>
          <surface>
            <friction>
              <ode>
                <mu>0.3</mu>
                <mu2>0.3</mu2>
              </ode>
              <torsional>
                <ode/>
              </torsional>
            </friction>
            <contact>
              <ode>
                <max_vel>0.1</max_vel>
                <min_depth>0.001</min_depth>
              </ode>
            </contact>
            <bounce/>
          </surface>
          <max_contacts>10</max_contacts>
        </collision>
        <visual name='visual'>
          <geometry>
            <mesh>
              <uri>model://cessna/meshes/cessna_front_wheel.dae</uri>
            </mesh>
          </geometry>
        </visual>
        <self_collide>0</self_collide>
        <enable_wind>0</enable_wind>
        <kinematic>0</kinematic>
      </link>
      <link name='rear_left_wheel'>
        <inertial>
          <mass>2</mass>
          <inertia>
            <ixx>0.035516</ixx>
            <ixy>0</ixy>
            <iyy>0.035516</iyy>
            <ixz>0</ixz>
            <iyz>0</iyz>
            <izz>0.0625</izz>
          </inertia>
          <pose>-1 1.27 -0.25 1.57079 -0 0</pose>
        </inertial>
        <collision name='collision'>
          <pose>-1 1.27 -0.25 1.57079 -0 0</pose>
          <geometry>
            <cylinder>
              <radius>0.25</radius>
              <length>0.16</length>
            </cylinder>
          </geometry>
          <surface>
            <friction>
              <ode>
                <mu>0.3</mu>
                <mu2>0.3</mu2>
              </ode>
              <torsional>
                <ode/>
              </torsional>
            </friction>
            <contact>
              <ode>
                <max_vel>0.1</max_vel>
                <min_depth>0.001</min_depth>
              </ode>
            </contact>
            <bounce/>
          </surface>
          <max_contacts>10</max_contacts>
        </collision>
        <visual name='visual'>
          <geometry>
            <mesh>
              <uri>model://cessna/meshes/cessna_rear_left_wheel.dae</uri>
            </mesh>
          </geometry>
        </visual>
        <self_collide>0</self_collide>
        <enable_wind>0</enable_wind>
        <kinematic>0</kinematic>
      </link>
      <link name='rear_right_wheel'>
        <inertial>
          <mass>2</mass>
          <inertia>
            <ixx>0.035516</ixx>
            <ixy>0</ixy>
            <iyy>0.035516</iyy>
            <ixz>0</ixz>
            <iyz>0</iyz>
            <izz>0.0625</izz>
          </inertia>
          <pose>-1 -1.27 -0.25 1.57079 -0 0</pose>
        </inertial>
        <collision name='collision'>
          <pose>-1 -1.27 -0.25 1.57079 -0 0</pose>
          <geometry>
            <cylinder>
              <radius>0.25</radius>
              <length>0.16</length>
            </cylinder>
          </geometry>
          <surface>
            <friction>
              <ode>
                <mu>0.3</mu>
                <mu2>0.3</mu2>
              </ode>
              <torsional>
                <ode/>
              </torsional>
            </friction>
            <contact>
              <ode>
                <max_vel>0.1</max_vel>
                <min_depth>0.001</min_depth>
              </ode>
            </contact>
            <bounce/>
          </surface>
          <max_contacts>10</max_contacts>
        </collision>
        <visual name='visual'>
          <geometry>
            <mesh>
              <uri>model://cessna/meshes/cessna_rear_right_wheel.dae</uri>
            </mesh>
          </geometry>
        </visual>
        <self_collide>0</self_collide>
        <enable_wind>0</enable_wind>
        <kinematic>0</kinematic>
      </link>
      <joint name='left_flap_joint' type='revolute'>
        <parent>body</parent>
        <child>left_flap</child>
        <pose>-1.6 1.55 1.43 0.02 -0 0</pose>
        <axis>
          <xyz>0 1 0</xyz>
          <limit>
            <lower>-0.53</lower>
            <upper>0.53</upper>
            <effort>-1</effort>
            <velocity>-1</velocity>
          </limit>
          <dynamics>
            <damping>1</damping>
            <spring_reference>0</spring_reference>
            <spring_stiffness>0</spring_stiffness>
          </dynamics>
        </axis>
        <physics>
          <ode>
            <implicit_spring_damper>1</implicit_spring_damper>
            <limit>
              <cfm>0</cfm>
              <erp>0.2</erp>
            </limit>
          </ode>
        </physics>
      </joint>
      <joint name='left_aileron_joint' type='revolute'>
        <parent>body</parent>
        <child>left_aileron</child>
        <pose>-1.45 3.7 1.5 0.05 -0 -0.12</pose>
        <axis>
          <xyz>0 1 0</xyz>
          <limit>
            <lower>-0.53</lower>
            <upper>0.53</upper>
            <effort>-1</effort>
            <velocity>-1</velocity>
          </limit>
          <dynamics>
            <damping>1</damping>
            <spring_reference>0</spring_reference>
            <spring_stiffness>0</spring_stiffness>
          </dynamics>
        </axis>
        <physics>
          <ode>
            <implicit_spring_damper>1</implicit_spring_damper>
            <limit>
              <cfm>0</cfm>
              <erp>0.2</erp>
            </limit>
          </ode>
        </physics>
      </joint>
      <joint name='right_flap_joint' type='revolute'>
        <parent>body</parent>
        <child>right_flap</child>
        <pose>-1.6 -1.55 1.43 -0.02 0 0</pose>
        <axis>
          <xyz>0 1 0</xyz>
          <limit>
            <lower>-0.53</lower>
            <upper>0.53</upper>
            <effort>-1</effort>
            <velocity>-1</velocity>
          </limit>
          <dynamics>
            <damping>1</damping>
            <spring_reference>0</spring_reference>
            <spring_stiffness>0</spring_stiffness>
          </dynamics>
        </axis>
        <physics>
          <ode>
            <implicit_spring_damper>1</implicit_spring_damper>
            <limit>
              <cfm>0</cfm>
              <erp>0.2</erp>
            </limit>
          </ode>
        </physics>
      </joint>
      <joint name='right_aileron_joint' type='revolute'>
        <parent>body</parent>
        <child>right_aileron</child>
        <pose>-1.45 -3.7 1.5 -0.05 -0 0.12</pose>
        <axis>
          <xyz>0 1 0</xyz>
          <limit>
            <lower>-0.53</lower>
            <upper>0.53</upper>
            <effort>-1</effort>
            <velocity>-1</velocity>
          </limit>
          <dynamics>
            <damping>1</damping>
            <spring_reference>0</spring_reference>
            <spring_stiffness>0</spring_stiffness>
          </dynamics>
        </axis>
        <physics>
          <ode>
            <implicit_spring_damper>1</implicit_spring_damper>
            <limit>
              <cfm>0</cfm>
              <erp>0.2</erp>
            </limit>
          </ode>
        </physics>
      </joint>
      <joint name='elevators_joint' type='revolute'>
        <parent>body</parent>
        <child>elevators</child>
        <pose>-5.55 0 0.57 0 -0 0</pose>
        <axis>
          <xyz>0 1 0</xyz>
          <limit>
            <lower>-0.53</lower>
            <upper>0.53</upper>
            <effort>-1</effort>
            <velocity>-1</velocity>
          </limit>
          <dynamics>
            <damping>1</damping>
            <spring_reference>0</spring_reference>
            <spring_stiffness>0</spring_stiffness>
          </dynamics>
        </axis>
        <physics>
          <ode>
            <implicit_spring_damper>1</implicit_spring_damper>
            <limit>
              <cfm>0</cfm>
              <erp>0.2</erp>
            </limit>
          </ode>
        </physics>
      </joint>
      <joint name='rudder_joint' type='revolute'>
        <parent>body</parent>
        <child>rudder</child>
        <pose>-5.9 0 1.3 0 -0.35 0</pose>
        <axis>
          <xyz>0 0 1</xyz>
          <limit>
            <lower>-0.53</lower>
            <upper>0.53</upper>
            <effort>-1</effort>
            <velocity>-1</velocity>
          </limit>
          <dynamics>
            <damping>1</damping>
            <spring_reference>0</spring_reference>
            <spring_stiffness>0</spring_stiffness>
          </dynamics>
        </axis>
        <physics>
          <ode>
            <implicit_spring_damper>1</implicit_spring_damper>
            <limit>
              <cfm>0</cfm>
              <erp>0.2</erp>
            </limit>
          </ode>
        </physics>
      </joint>
      <joint name='propeller_joint' type='revolute'>
        <parent>body</parent>
        <child>propeller</child>
        <axis>
          <xyz>1 0 0</xyz>
          <limit>
            <lower>-1e+12</lower>
            <upper>1e+12</upper>
            <effort>-1</effort>
            <velocity>-1</velocity>
          </limit>
          <dynamics>
            <damping>0.001</damping>
            <spring_reference>0</spring_reference>
            <spring_stiffness>0</spring_stiffness>
          </dynamics>
        </axis>
        <physics>
          <ode>
            <implicit_spring_damper>1</implicit_spring_damper>
            <limit>
              <cfm>0</cfm>
              <erp>0.2</erp>
            </limit>
          </ode>
        </physics>
      </joint>
      <joint name='front_wheel_joint' type='revolute'>
        <parent>body</parent>
        <child>front_wheel</child>
        <pose>0.712 0 -0.313 0 -0 0</pose>
        <axis>
          <xyz>0 1 0</xyz>
          <limit>
            <lower>-1e+12</lower>
            <upper>1e+12</upper>
            <effort>-1</effort>
            <velocity>-1</velocity>
          </limit>
          <dynamics>
            <damping>0.01</damping>
            <spring_reference>0</spring_reference>
            <spring_stiffness>0</spring_stiffness>
          </dynamics>
        </axis>
        <physics>
          <ode>
            <implicit_spring_damper>1</implicit_spring_damper>
            <limit>
              <cfm>0</cfm>
              <erp>0.2</erp>
            </limit>
          </ode>
        </physics>
      </joint>
      <joint name='rear_left_wheel_joint' type='revolute'>
        <parent>body</parent>
        <child>rear_left_wheel</child>
        <pose>-1 -1.27 -0.25 0 -0 0</pose>
        <axis>
          <xyz>0 1 0</xyz>
          <limit>
            <lower>-1e+12</lower>
            <upper>1e+12</upper>
            <effort>-1</effort>
            <velocity>-1</velocity>
          </limit>
          <dynamics>
            <damping>0.01</damping>
            <spring_reference>0</spring_reference>
            <spring_stiffness>0</spring_stiffness>
          </dynamics>
        </axis>
        <physics>
          <ode>
            <implicit_spring_damper>1</implicit_spring_damper>
            <limit>
              <cfm>0</cfm>
              <erp>0.2</erp>
            </limit>
          </ode>
        </physics>
      </joint>
      <joint name='rear_right_wheel_joint' type='revolute'>
        <parent>body</parent>
        <child>rear_right_wheel</child>
        <pose>-1 1.27 -0.25 0 -0 0</pose>
        <axis>
          <xyz>0 1 0</xyz>
          <limit>
            <lower>-1e+12</lower>
            <upper>1e+12</upper>
            <effort>-1</effort>
            <velocity>-1</velocity>
          </limit>
          <dynamics>
            <damping>0.01</damping>
            <spring_reference>0</spring_reference>
            <spring_stiffness>0</spring_stiffness>
          </dynamics>
        </axis>
        <physics>
          <ode>
            <implicit_spring_damper>1</implicit_spring_damper>
            <limit>
              <cfm>0</cfm>
              <erp>0.2</erp>
            </limit>
          </ode>
        </physics>
      </joint>
    </model>
    <model name='cinder_block'>
      <link name='link'>
        <inertial>
          <pose>0 0 0.1016 0 -0 0</pose>
          <mass>5</mass>
          <inertia>
            <ixx>0.028705</ixx>
            <ixy>0</ixy>
            <iyy>0.073708</iyy>
            <ixz>0</ixz>
            <iyz>0</iyz>
            <izz>0.06908</izz>
          </inertia>
        </inertial>
        <visual name='visual'>
          <geometry>
            <mesh>
              <uri>model://cinder_block/meshes/cinder_block.dae</uri>
            </mesh>
          </geometry>
        </visual>
        <collision name='left'>
          <pose>0 -0.08465 0.1016 0 -0 0</pose>
          <geometry>
            <box>
              <size>0.43495 0.0339 0.2032</size>
            </box>
          </geometry>
          <surface>
            <contact>
              <ode>
                <max_vel>0.1</max_vel>
                <min_depth>0.001</min_depth>
              </ode>
            </contact>
            <friction>
              <ode>
                <mu>1</mu>
                <mu2>1</mu2>
              </ode>
              <torsional>
                <ode/>
              </torsional>
            </friction>
            <bounce/>
          </surface>
          <max_contacts>10</max_contacts>
        </collision>
        <collision name='right'>
          <pose>0 0.08465 0.1016 0 -0 0</pose>
          <geometry>
            <box>
              <size>0.43495 0.0339 0.2032</size>
            </box>
          </geometry>
          <surface>
            <contact>
              <ode>
                <max_vel>0.1</max_vel>
                <min_depth>0.001</min_depth>
              </ode>
            </contact>
            <friction>
              <ode>
                <mu>1</mu>
                <mu2>1</mu2>
              </ode>
              <torsional>
                <ode/>
              </torsional>
            </friction>
            <bounce/>
          </surface>
          <max_contacts>10</max_contacts>
        </collision>
        <collision name='front'>
          <pose>0.18625 0 0.1016 0 -0 0</pose>
          <geometry>
            <box>
              <size>0.0339 0.1354 0.203</size>
            </box>
          </geometry>
          <surface>
            <contact>
              <ode>
                <max_vel>0.1</max_vel>
                <min_depth>0.001</min_depth>
              </ode>
            </contact>
            <friction>
              <ode>
                <mu>1</mu>
                <mu2>1</mu2>
              </ode>
              <torsional>
                <ode/>
              </torsional>
            </friction>
            <bounce/>
          </surface>
          <max_contacts>10</max_contacts>
        </collision>
        <collision name='middle'>
          <pose>0 0 0.1016 0 -0 0</pose>
          <geometry>
            <box>
              <size>0.0339 0.1354 0.203</size>
            </box>
          </geometry>
          <surface>
            <contact>
              <ode>
                <max_vel>0.1</max_vel>
                <min_depth>0.001</min_depth>
              </ode>
            </contact>
            <friction>
              <ode>
                <mu>1</mu>
                <mu2>1</mu2>
              </ode>
              <torsional>
                <ode/>
              </torsional>
            </friction>
            <bounce/>
          </surface>
          <max_contacts>10</max_contacts>
        </collision>
        <collision name='back'>
          <pose>-0.18625 0 0.1016 0 -0 0</pose>
          <geometry>
            <box>
              <size>0.0339 0.1354 0.203</size>
            </box>
          </geometry>
          <surface>
            <contact>
              <ode>
                <max_vel>0.1</max_vel>
                <min_depth>0.001</min_depth>
              </ode>
            </contact>
            <friction>
              <ode>
                <mu>1</mu>
                <mu2>1</mu2>
              </ode>
              <torsional>
                <ode/>
              </torsional>
            </friction>
            <bounce/>
          </surface>
          <max_contacts>10</max_contacts>
        </collision>
        <self_collide>0</self_collide>
        <enable_wind>0</enable_wind>
        <kinematic>0</kinematic>
      </link>
      <pose>1.30604 -1.14938 0 0 -0 0</pose>
    </model>
    <model name='cinder_block_2'>
      <link name='link'>
        <inertial>
          <pose>0 0 0.071438 0 -0 0</pose>
          <mass>5</mass>
          <inertia>
            <ixx>0.06908</ixx>
            <ixy>0</ixy>
            <iyy>0.028705</iyy>
            <ixz>0</ixz>
            <iyz>0</iyz>
            <izz>0.073708</izz>
          </inertia>
        </inertial>
        <visual name='visual'>
          <geometry>
            <mesh>
              <uri>model://cinder_block_2/meshes/cinder_block.dae</uri>
            </mesh>
          </geometry>
        </visual>
        <collision name='top'>
          <pose>0 0 0.130175 0 -0 0</pose>
          <geometry>
            <box>
              <size>0.19368 0.396875 0.0254</size>
            </box>
          </geometry>
          <surface>
            <contact>
              <ode>
                <max_vel>0.1</max_vel>
                <min_depth>0.001</min_depth>
              </ode>
            </contact>
            <friction>
              <ode>
                <mu>1</mu>
                <mu2>1</mu2>
              </ode>
              <torsional>
                <ode/>
              </torsional>
            </friction>
            <bounce/>
          </surface>
          <max_contacts>10</max_contacts>
        </collision>
        <collision name='bottom'>
          <pose>0 0 0.0127 0 -0 0</pose>
          <geometry>
            <box>
              <size>0.19368 0.396875 0.0254</size>
            </box>
          </geometry>
          <surface>
            <contact>
              <ode>
                <max_vel>0.1</max_vel>
                <min_depth>0.001</min_depth>
              </ode>
            </contact>
            <friction>
              <ode>
                <mu>1</mu>
                <mu2>1</mu2>
              </ode>
              <torsional>
                <ode/>
              </torsional>
            </friction>
            <bounce/>
          </surface>
          <max_contacts>10</max_contacts>
        </collision>
        <collision name='left'>
          <pose>0 -0.185738 0.071438 0 -0 0</pose>
          <geometry>
            <box>
              <size>0.19368 0.0254 0.092075</size>
            </box>
          </geometry>
          <surface>
            <contact>
              <ode>
                <max_vel>0.1</max_vel>
                <min_depth>0.001</min_depth>
              </ode>
            </contact>
            <friction>
              <ode>
                <mu>1</mu>
                <mu2>1</mu2>
              </ode>
              <torsional>
                <ode/>
              </torsional>
            </friction>
            <bounce/>
          </surface>
          <max_contacts>10</max_contacts>
        </collision>
        <collision name='right'>
          <pose>0 0.185738 0.071438 0 -0 0</pose>
          <geometry>
            <box>
              <size>0.19368 0.0254 0.092075</size>
            </box>
          </geometry>
          <surface>
            <contact>
              <ode>
                <max_vel>0.1</max_vel>
                <min_depth>0.001</min_depth>
              </ode>
            </contact>
            <friction>
              <ode>
                <mu>1</mu>
                <mu2>1</mu2>
              </ode>
              <torsional>
                <ode/>
              </torsional>
            </friction>
            <bounce/>
          </surface>
          <max_contacts>10</max_contacts>
        </collision>
        <collision name='middle'>
          <pose>0 0 0.071438 0 -0 0</pose>
          <geometry>
            <box>
              <size>0.19368 0.0254 0.092075</size>
            </box>
          </geometry>
          <surface>
            <contact>
              <ode>
                <max_vel>0.1</max_vel>
                <min_depth>0.001</min_depth>
              </ode>
            </contact>
            <friction>
              <ode>
                <mu>1</mu>
                <mu2>1</mu2>
              </ode>
              <torsional>
                <ode/>
              </torsional>
            </friction>
            <bounce/>
          </surface>
          <max_contacts>10</max_contacts>
        </collision>
        <self_collide>0</self_collide>
        <enable_wind>0</enable_wind>
        <kinematic>0</kinematic>
      </link>
      <pose>1.43904 -1.91708 0 0 -0 0</pose>
    </model>
    <model name='Construction Cone'>
      <link name='link'>
        <collision name='collision'>
          <geometry>
            <mesh>
              <scale>10 10 10</scale>
              <uri>model://construction_cone/meshes/construction_cone.dae</uri>
            </mesh>
          </geometry>
          <max_contacts>10</max_contacts>
          <surface>
            <contact>
              <ode/>
            </contact>
            <bounce/>
            <friction>
              <torsional>
                <ode/>
              </torsional>
              <ode/>
            </friction>
          </surface>
        </collision>
        <visual name='visual'>
          <geometry>
            <mesh>
              <scale>10 10 10</scale>
              <uri>model://construction_cone/meshes/construction_cone.dae</uri>
            </mesh>
          </geometry>
        </visual>
        <self_collide>0</self_collide>
        <inertial>
          <pose>0 0 0 0 -0 0</pose>
          <inertia>
            <ixx>1</ixx>
            <ixy>0</ixy>
            <ixz>0</ixz>
            <iyy>1</iyy>
            <iyz>0</iyz>
            <izz>1</izz>
          </inertia>
          <mass>1</mass>
        </inertial>
        <enable_wind>0</enable_wind>
        <kinematic>0</kinematic>
      </link>
      <pose>0.016478 0.275587 0 0 -0 0</pose>
    </model>
    <model name='Dumpster'>
      <link name='link'>
        <collision name='collision'>
          <geometry>
            <mesh>
              <scale>1.5 1.5 1.5</scale>
              <uri>model://dumpster/meshes/dumpster.dae</uri>
            </mesh>
          </geometry>
          <max_contacts>10</max_contacts>
          <surface>
            <contact>
              <ode/>
            </contact>
            <bounce/>
            <friction>
              <torsional>
                <ode/>
              </torsional>
              <ode/>
            </friction>
          </surface>
        </collision>
        <visual name='visual'>
          <geometry>
            <mesh>
              <scale>1.5 1.5 1.5</scale>
              <uri>model://dumpster/meshes/dumpster.dae</uri>
            </mesh>
          </geometry>
          <material>
            <script>
              <uri>model://dumpster/materials/scripts</uri>
              <uri>model://dumpster/materials/textures</uri>
              <name>Dumpster/Diffuse</name>
            </script>
          </material>
        </visual>
        <self_collide>0</self_collide>
        <inertial>
          <pose>0 0 0 0 -0 0</pose>
          <inertia>
            <ixx>1</ixx>
            <ixy>0</ixy>
            <ixz>0</ixz>
            <iyy>1</iyy>
            <iyz>0</iyz>
            <izz>1</izz>
          </inertia>
          <mass>1</mass>
        </inertial>
        <enable_wind>0</enable_wind>
        <kinematic>0</kinematic>
      </link>
      <pose>2.13743 0.686572 0 0 -0 0</pose>
    </model>
    <state world_name='default'>
      <sim_time>1063 128000000</sim_time>
      <real_time>1064 968609260</real_time>
      <wall_time>1708283275 794999530</wall_time>
      <iterations>1063128</iterations>
      <model name='Construction Cone'>
        <pose>0.016478 0.275587 -1e-05 -1e-06 0 0</pose>
        <scale>1 1 1</scale>
        <link name='link'>
          <pose>0.016478 0.275587 -1e-05 -1e-06 0 0</pose>
          <velocity>0 0 0 0 -0 0</velocity>
          <acceleration>0 0 -9.8 0 -0 0</acceleration>
          <wrench>0 0 -9.8 0 -0 0</wrench>
        </link>
      </model>
      <model name='Dumpster'>
        <pose>2.13743 0.686572 0.001376 2e-06 -0 0</pose>
        <scale>1 1 1</scale>
        <link name='link'>
          <pose>2.13743 0.686572 0.001376 2e-06 -0 0</pose>
          <velocity>0 0 0 0 -0 0</velocity>
          <acceleration>0 0 -9.8 0 -0 0</acceleration>
          <wrench>0 0 -9.8 0 -0 0</wrench>
        </link>
      </model>
      <model name='cabinet'>
        <pose>-0.185929 -0.852549 0 0 -0 0</pose>
        <scale>1 1 1</scale>
        <link name='cabinet_bottom_plate'>
          <pose>-0.185929 -0.852549 0 0 -0 0</pose>
          <velocity>0 0 0 0 -0 0</velocity>
          <acceleration>0 0 0 0 -0 0</acceleration>
          <wrench>0 0 0 0 -0 0</wrench>
        </link>
      </model>
      <model name='cessna_c172'>
        <pose>-2.30353 4.73052 0.492378 -8.9e-05 -0.00069 -0.006825</pose>
        <scale>1 1 1</scale>
        <link name='body'>
          <pose>-2.30353 4.73052 0.492378 -8.9e-05 -0.00069 -0.006825</pose>
          <velocity>0.001951 -0.003328 -0.004351 0.003356 -0.002551 0.001502</velocity>
          <acceleration>-0.000261 -0.530356 1.16442 -0.151338 -0.286342 -0.030104</acceleration>
          <wrench>-0.177798 -360.848 792.256 0 -0 0</wrench>
        </link>
        <link name='elevators'>
          <pose>-2.77884 4.73402 3.37612 -0.000103 -0.530721 -0.006773</pose>
          <velocity>-0.073476 -0.013243 0.143581 0.003155 -0.031908 0.001505</velocity>
          <acceleration>3.15304 -0.450546 -5.44208 -0.562533 0.811404 -0.027792</acceleration>
          <wrench>6.30609 -0.901091 -10.8842 0 -0 0</wrench>
        </link>
        <link name='front_wheel'>
          <pose>-2.29227 4.7304 0.516982 8.9e-05 0.033966 -0.006824</pose>
          <velocity>0.007762 -0.022933 0.018068 0.043576 0.015009 0.000819</velocity>
          <acceleration>0.285077 -3.44907 37.2507 2.02852 -0.889522 2.04487</acceleration>
          <wrench>0.570155 -6.89814 74.5015 0 -0 0</wrench>
        </link>
        <link name='left_aileron'>
          <pose>-1.90411 4.6225 1.62451 -0.062167 -0.52673 -0.017185</pose>
          <velocity>-0.002029 -0.005518 -0.020675 0.004285 0.004742 0.00187</velocity>
          <acceleration>0.110876 -0.418672 -0.335025 2.80744 -1.50998 3.043</acceleration>
          <wrench>0.221751 -0.837344 -0.670049 0 -0 0</wrench>
        </link>
        <link name='left_flap'>
          <pose>-1.81678 4.70728 1.49327 0.003085 -0.530575 -0.018494</pose>
          <velocity>-0.000908 -0.005919 -0.005016 0.003361 -0.001689 0.001519</velocity>
          <acceleration>-0.071233 -0.41809 0.314552 -0.15312 -0.271017 -0.031906</acceleration>
          <wrench>-0.142466 -0.836179 0.629103 0 -0 0</wrench>
        </link>
        <link name='propeller'>
          <pose>-0.51416 4.71839 1.34861 0.004171 -0.00069 -0.006825</pose>
          <velocity>-0.000215 -0.003244 0.000178 9.5e-05 -0.002525 0.001732</velocity>
          <acceleration>0.020075 -0.469259 1.61598 -0.002037 -0.263415 0.229093</acceleration>
          <wrench>0.368782 -8.62029 29.6855 0 -0 0</wrench>
        </link>
        <link name='rear_left_wheel'>
          <pose>-2.30613 4.73083 0.511916 -0.001242 -0.010838 -0.006818</pose>
          <velocity>0.004506 -0.006502 -0.02392 0.014809 0.006027 0.001099</velocity>
          <acceleration>-0.284606 -0.546485 -0.066952 2.19114 -1.14426 -0.01216</acceleration>
          <wrench>-0.569212 -1.09297 -0.133904 0 -0 0</wrench>
        </link>
        <link name='rear_right_wheel'>
          <pose>-2.33039 4.73031 0.591169 0.001071 -0.091521 -0.006929</pose>
          <velocity>0.011451 -0.007815 0.000745 0.01504 0.021683 0.001104</velocity>
          <acceleration>-0.102449 -0.55149 -0.03982 2.20774 -0.418942 0.045492</acceleration>
          <wrench>-0.204897 -1.10298 -0.07964 0 -0 0</wrench>
        </link>
        <link name='right_aileron'>
          <pose>-1.90267 4.83328 1.62448 0.061961 -0.526725 0.003639</pose>
          <velocity>-0.002224 -0.007424 -0.018382 0.002608 0.004028 0.00117</velocity>
          <acceleration>-3.3826 -0.493542 6.14126 2.71657 0.258555 -1.64906</acceleration>
          <wrench>-6.76521 -0.987083 12.2825 0 -0 0</wrench>
        </link>
        <link name='right_flap'>
          <pose>-1.8165 4.7473 1.49328 -0.003292 -0.530581 0.004949</pose>
          <velocity>-0.001783 -0.006072 -0.009234 0.003375 0.000376 0.001444</velocity>
          <acceleration>-0.114762 -0.420011 0.689039 -0.159427 -0.758514 -0.022742</acceleration>
          <wrench>-0.229525 -0.840021 1.37808 0 -0 0</wrench>
        </link>
        <link name='rudder'>
          <pose>-2.3035 4.73543 0.492377 -0.00042 -0.00069 -0.00592</pose>
          <velocity>3.8e-05 -0.326332 -0.004164 0.025128 -0.002711 -0.058018</velocity>
          <acceleration>-0.10693 -0.215297 -0.585529 -0.011744 -0.310371 -0.414413</acceleration>
          <wrench>-0.21386 -0.430595 -1.17106 0 -0 0</wrench>
        </link>
      </model>
      <model name='cinder_block'>
        <pose>1.30604 -1.14938 -6e-06 0 2.8e-05 0</pose>
        <scale>1 1 1</scale>
        <link name='link'>
          <pose>1.30604 -1.14938 -6e-06 0 2.8e-05 0</pose>
          <velocity>0 0 0 0 -0 0</velocity>
          <acceleration>0 -0 0 0 -0 0</acceleration>
          <wrench>0 -0 0 0 -0 0</wrench>
        </link>
      </model>
      <model name='cinder_block_2'>
        <pose>1.43904 -1.91708 -1e-05 0 -0 0</pose>
        <scale>1 1 1</scale>
        <link name='link'>
          <pose>1.43904 -1.91708 -1e-05 0 -0 0</pose>
          <velocity>0 0 0 0 -0 0</velocity>
          <acceleration>-0 0 -0 -0 -0 -0</acceleration>
          <wrench>-0 0 -0 0 -0 0</wrench>
        </link>
      </model>
      <model name='ground_plane'>
        <pose>0 0 0 0 -0 0</pose>
        <scale>1 1 1</scale>
        <link name='link'>
          <pose>0 0 0 0 -0 0</pose>
          <velocity>0 0 0 0 -0 0</velocity>
          <acceleration>0 0 0 0 -0 0</acceleration>
          <wrench>0 0 0 0 -0 0</wrench>
        </link>
      </model>
      <light name='sun'>
        <pose>0 0 10 0 -0 0</pose>
      </light>
    </state>
    <gui fullscreen='0'>
      <camera name='user_camera'>
        <pose>9.62423 -10.8332 9.61594 0 0.603643 2.24019</pose>
        <view_controller>orbit</view_controller>
        <projection_type>perspective</projection_type>
      </camera>
    </gui>
  </world>
</sdf>
